<?xml version="1.0" ?>
<!-- =================================================================================== -->
<!-- |    This document was autogenerated by xacro from robot_simple.urdf.xacro        | -->
<!-- |    EDITING THIS FILE BY HAND IS NOT RECOMMENDED                                 | -->
<!-- =================================================================================== -->
<robot name="robot">
  <!-- Specify some standard inertial calculations https://en.wikipedia.org/wiki/List_of_moments_of_inertia -->
  <!-- These make use of xacro's mathematical functionality -->
  <material name="white">
    <color rgba="1 1 1 1"/>
  </material>
  <material name="orange">
    <color rgba="1 0.3 0.1 1"/>
  </material>
  <material name="blue">
    <color rgba="0.2 0.2 1 1"/>
  </material>
  <material name="black">
    <color rgba="0 0 0 1"/>
  </material>
  <material name="red">
    <color rgba="1 0 0 1"/>
  </material>
  <material name="green">
    <color rgba="0 1 0 1"/>
  </material>
  <material name="yellow">
    <color rgba="1 1 0 1"/>
  </material>
  <material name="purple">
    <color rgba="0.5 0 0.5 1"/>
  </material>
  <material name="cyan">
    <color rgba="0 1 1 1"/>
  </material>
  <material name="magenta">
    <color rgba="1 0 1 1"/>
  </material>
  <material name="gray">
    <color rgba="0.5 0.5 0.5 1"/>
  </material>
  <material name="dark_gray">
    <color rgba="0.25 0.25 0.25 1"/>
  </material>
  <material name="light_gray">
    <color rgba="0.75 0.75 0.75 1"/>
  </material>
  <material name="brown">
    <color rgba="0.6 0.3 0.1 1"/>
  </material>
  <material name="light_blue">
    <color rgba="0.5 0.7 1 1"/>
  </material>
  <material name="lime">
    <color rgba="0.7 1 0 1"/>
  </material>
  <material name="pink">
    <color rgba="1 0.6 0.8 1"/>
  </material>
  <material name="teal">
    <color rgba="0 0.5 0.5 1"/>
  </material>
  <material name="navy">
    <color rgba="0 0 0.5 1"/>
  </material>
  <!-- BASE LINK -->
  <link name="base_link">

    </link>
  <!-- BASE_FOOTPRINT LINK -->
  <joint name="base_footprint_joint" type="fixed">
    <parent link="base_link"/>
    <child link="base_footprint"/>
    <origin rpy="0 0 0" xyz="0 0 0"/>
  </joint>
  <link name="base_footprint">
    </link>
  <!-- CHASSIS LINK -->
  <joint name="chassis_joint" type="fixed">
    <parent link="base_link"/>
    <child link="chassis"/>
    <origin xyz="0 0 -0.01"/>
  </joint>
  <link name="chassis">
    <visual>
      <origin xyz="0.3 0 0.1"/>
      <geometry>
        <box size="0.6 0.4 0.2"/>
      </geometry>
      <material name="orange"/>
    </visual>
    <collision>
      <origin xyz="0.3 0 0.1"/>
      <geometry>
        <box size="0.6 0.4 0.2"/>
      </geometry>
    </collision>
    <inertial>
      <origin rpy="0 0 0" xyz="0.3 0 0.1"/>
      <mass value="0.5"/>
      <inertia ixx="0.008333333333333335" ixy="0.0" ixz="0.0" iyy="0.016666666666666666" iyz="0.0" izz="0.021666666666666667"/>
    </inertial>
  </link>
  <gazebo reference="chassis">
    <material>Gazebo/Orange</material>
  </gazebo>
  <!-- LEFT WHEEL LINK -->
  <joint name="front_left_wheel_joint" type="continuous">
    <parent link="base_link"/>
    <child link="front_left_wheel"/>
    <origin rpy="-1.5707963267948966 0 0" xyz="0.5  0.225 0"/>
    <axis xyz="0 0 1"/>
  </joint>
  <link name="front_left_wheel">
    <visual>
      <geometry>
        <cylinder length="0.05" radius="0.075"/>
      </geometry>
      <material name="blue"/>
    </visual>
    <collision>
      <geometry>
        <sphere radius="0.075"/>
      </geometry>
    </collision>
    <inertial>
      <origin rpy="0 0 0" xyz="0 0 0"/>
      <mass value="0.05"/>
      <inertia ixx="8.072916666666665e-05" ixy="0.0" ixz="0.0" iyy="8.072916666666665e-05" iyz="0.0" izz="0.000140625"/>
    </inertial>
  </link>
  <gazebo reference="front_left_wheel">
    <material>Gazebo/Blue</material>
  </gazebo>
  <joint name="rear_left_wheel_joint" type="continuous">
    <parent link="base_link"/>
    <child link="rear_left_wheel"/>
    <origin rpy="-1.5707963267948966 0 0" xyz="0.09999999999999998 0.225 0"/>
    <axis xyz="0 0 1"/>
  </joint>
  <link name="rear_left_wheel">
    <visual>
      <geometry>
        <cylinder length="0.05" radius="0.075"/>
      </geometry>
      <material name="blue"/>
    </visual>
    <collision>
      <geometry>
        <sphere radius="0.075"/>
      </geometry>
    </collision>
    <inertial>
      <origin rpy="0 0 0" xyz="0 0 0"/>
      <mass value="0.05"/>
      <inertia ixx="8.072916666666665e-05" ixy="0.0" ixz="0.0" iyy="8.072916666666665e-05" iyz="0.0" izz="0.000140625"/>
    </inertial>
  </link>
  <gazebo reference="rear_left_wheel">
    <material>Gazebo/Blue</material>
  </gazebo>
  <!-- RIGHT WHEEL LINK -->
  <joint name="front_right_wheel_joint" type="continuous">
    <parent link="base_link"/>
    <child link="front_right_wheel"/>
    <origin rpy="1.5707963267948966 0 0" xyz="0.5 -0.225 0"/>
    <axis xyz="0 0 1"/>
  </joint>
  <link name="front_right_wheel">
    <visual>
      <geometry>
        <cylinder length="0.05" radius="0.075"/>
      </geometry>
      <material name="blue"/>
    </visual>
    <collision>
      <geometry>
        <sphere radius="0.075"/>
      </geometry>
    </collision>
    <inertial>
      <origin rpy="0 0 0" xyz="0 0 0"/>
      <mass value="0.05"/>
      <inertia ixx="8.072916666666665e-05" ixy="0.0" ixz="0.0" iyy="8.072916666666665e-05" iyz="0.0" izz="0.000140625"/>
    </inertial>
  </link>
  <gazebo reference="front_right_wheel">
    <material>Gazebo/Blue</material>
  </gazebo>
  <joint name="rear_right_wheel_joint" type="continuous">
    <parent link="base_link"/>
    <child link="rear_right_wheel"/>
    <origin rpy="1.5707963267948966 0 0" xyz="0.09999999999999998 -0.225 0"/>
    <axis xyz="0 0 1"/>
  </joint>
  <link name="rear_right_wheel">
    <visual>
      <geometry>
        <cylinder length="0.05" radius="0.075"/>
      </geometry>
      <material name="blue"/>
    </visual>
    <collision>
      <geometry>
        <sphere radius="0.075"/>
      </geometry>
    </collision>
    <inertial>
      <origin rpy="0 0 0" xyz="0 0 0"/>
      <mass value="0.05"/>
      <inertia ixx="8.072916666666665e-05" ixy="0.0" ixz="0.0" iyy="8.072916666666665e-05" iyz="0.0" izz="0.000140625"/>
    </inertial>
  </link>
  <gazebo reference="rear_right_wheel">
    <material>Gazebo/Blue</material>
  </gazebo>
  <gazebo>
    <plugin filename="gz-sim-diff-drive-system" name="gz::sim::systems::DiffDrive">
      <topic>cmd_vel</topic>
      <!-- <frame_id>odom</frame_id> -->
      <child_frame_id>base_footprint</child_frame_id>
      <odom_topic>odom/unfiltered</odom_topic>
      <!-- <tf_topic>/tf</tf_topic> -->
      <left_joint>rear_left_wheel_joint</left_joint>
      <right_joint>rear_right_wheel_joint</right_joint>
      <wheel_separation>0.45</wheel_separation>
      <wheel_radius>0.075</wheel_radius>
      <max_linear_acceleration>1</max_linear_acceleration>
      <min_linear_acceleration>-1</min_linear_acceleration>
      <max_angular_acceleration>2</max_angular_acceleration>
      <min_angular_acceleration>-2</min_angular_acceleration>
      <max_linear_velocity>0.5</max_linear_velocity>
      <min_linear_velocity>-0.5</min_linear_velocity>
      <max_angular_velocity>1</max_angular_velocity>
      <min_angular_velocity>-1</min_angular_velocity>
    </plugin>
  </gazebo>
</robot>
